Workbook
Name budget: Budget_Dashboard!$L1
Name budget_range: Budget_Dashboard!$Q1
Name budget_rank: Budget_Dashboard!$R1
Name cc_budget: Calculations!$K$54
Name cc_budget: Calculations!$K1
Name cc_delta: Calculations!$L1
Name cc_in_focus: Calculations!$G1
Name cc_month_no: Calculations!$F1
Name cc_show_remaining_budget: Calculations!$I1
Name cc_show_type: Calculations!$H1
Name cc_tracked: Calculations!$J1
Name cc_type: Calculations!$E1
Name comb_rank: Budget_Dashboard!$S1
Name comb_rank_norm: Budget_Dashboard!$U1
Name comb_rank_norm_run_range: Budget_Dashboard!$V1
Name comb_rank_range: Budget_Dashboard!$T1
Name comb_rank_unique: Budget_Dashboard!$W1
Name current_date: TODAY()
Name expenses_header_row: ROW(Expenses[[#Headers],[Expenses]])
Name expenses_max_row: MAX(ROW(Expenses[]))
Name expenses_min_row: MIN(ROW(Expenses[]))
Name expenses_total_row: ROW(Budget_Planning!$C$33)
Name header_row_id: Budget_Dashboard!$D1
Name income_header_row: ROW(Income[[#Headers],[Income]])
Name income_max_row: MAX(ROW(Income[]))
Name income_min_row: MIN(ROW(Income[]))
Name income_total_row: ROW(Budget_Planning!$C$20)
Name is_cat: Budget_Dashboard!$F1
Name is_empty: Budget_Dashboard!$H1
Name is_header: Budget_Dashboard!$E1
Name is_total: Budget_Dashboard!$G1
Name item: Budget_Dashboard!$J1
Name out_budget: Budget_Dashboard!$AA1
Name out_percentage_completed: Budget_Dashboard!$AB1
Name out_tracked: Budget_Dashboard!$Z1
Name row_id: Budget_Dashboard!$C1
Name Savings_header_row: ROW(Savings[[#Headers],[Savings]])
Name savings_max_row: MAX(ROW(Savings[]))
Name savings_min_row: MIN(ROW(Savings[]))
Name savings_rate_calculation_type: Settings!$E$22
Name savings_total_row: ROW(Budget_Planning!$C$46)
Name Selected_period: Calculations!$E$20
Name selected_period_display: Calculations!$E$21
Name Selected_Year: Calculations!$E$19
Name shift_late_income_starting_day: Settings!$E$17
Name shift_late_income_status: Settings!$E$15
Name sort_max_row: Budget_Dashboard!$N1
Name sort_min_row: Budget_Dashboard!$M1
Name starting_year: Budget_Planning!$E$5
Name tracked: Budget_Dashboard!$K1
Name tracked_range: Budget_Dashboard!$O1
Name tracked_rank: Budget_Dashboard!$P1
Name type: Budget_Dashboard!$I1

Sheet Settings
B2: Settings
D6: General
D8: Starting Year: | E8: 2022 | G8: set the starting year(yyyy) at the beginning and do not change it again.
D12: Budget Tracking & Dashboard
C14: Late monthly income
C15: Shift Late Income | E15: Active | G15: Activate this option to treate late income received on or after a certain day of a month as income for a next month.This specially recommended in case you receive your monthly paycheck at the end of the month and prefer to consider this income as the disposable income for next month.
C17: starting on day x in month: | E17: 20
D20: KPI Calculation in Dashboard
D22: Savings rate as % of income: | E22: % allocated to savings | G22: Choose how you want the savings rate(SR) to be calculated in the dashboard KPI tiles:
G23: 1.)Active Option(% allocated to savings): SR=Savings/Income
G24: 2.)Passive Option(% allocated to expenses): SR=(Income-Expenses)/Income

Sheet Budget_Planning
C2: Budget Planning
C5: Define starting year in settings -> | E5: 2022 | S5: 2023 | AG5: 2024 | AU5: 2025 | BI5: 2026 | BW5: 2027 | CK5: 2028 | CY5: 2029 | DM5: 2030
E6: =IF(E7=0,"Yes","Jan") -> Yes | F6: =IF(F7=0, "Yes", "Feb") -> Yes | G6: =IF(G7=0, "Yes", "Mar") -> Yes | H6: =IF(H7=0, "Yes", "Apr") -> Yes | I6: =IF(I7=0, "Yes", "May") -> Yes | J6: =IF(J7=0, "Yes", "Jun") -> Yes | K6: =IF(K7=0, "Yes", "Jul") -> Yes | L6: =IF(L7=0, "Yes", "Aug") -> Yes | M6: =IF(M7=0, "Yes", "Sep") -> Yes | N6: =IF(N7=0, "Yes", "Oct") -> Yes | O6: =IF(O7=0, "Yes", "Nov") -> Yes | P6: =IF(P7=0, "Yes", "Dec") -> Yes | Q6: =IF(Q7=0, "Yes", "Total") -> Yes | S6: =IF(T7=0, "Yes", "Jan") -> Yes | T6: =IF(T7>=0, "Yes", "Feb") -> Yes | U6: =IF(U7=0, "Yes", "Mar") -> Yes | V6: =IF(V7=0, "Yes", "Apr") -> Yes | W6: =IF(W7=0, "Yes", "May") -> Yes | X6: =IF(X7=0, "Yes", "Jun") -> Yes | Y6: =IF(Y7=0, "Yes", "Jul") -> Yes | Z6: =IF(Z7=0, "Yes", "Aug") -> Yes | AA6: =IF(AA7=0, "Yes", "Sep") -> Yes | AB6: =IF(AB7=0, "Yes", "Oct") -> Yes | AC6: =IF(AC7=0, "Yes", "Nov") -> Yes | AD6: =IF(AD7=0, "Yes", "Dec") -> Yes | AE6: =IF(AE7=0, "Yes", "Total") -> Yes | AG6: =IF(AH7=0, "Yes", "Jan") -> Yes | AH6: =IF(AH7>=0, "Yes", "Feb") -> Yes | AI6: =IF(AI7=0, "Yes", "Mar") -> Yes | AJ6: =IF(AJ7=0, "Yes", "Apr") -> Yes | AK6: =IF(AK7=0, "Yes", "May") -> Yes | AL6: =IF(AL7=0, "Yes", "Jun") -> Yes | AM6: =IF(AM7=0, "Yes", "Jul") -> Yes | AN6: =IF(AN7=0, "Yes", "Aug") -> Yes | AO6: =IF(AO7=0, "Yes", "Sep") -> Yes | AP6: =IF(AP7=0, "Yes", "Oct") -> Yes | AQ6: =IF(AQ7=0, "Yes", "Nov") -> Yes | AR6: =IF(AR7=0, "Yes", "Dec") -> Yes | AS6: =IF(AS7=0, "Yes", "Total") -> Yes | AU6: =IF(AV7=0, "Yes", "Jan") -> Yes | AV6: =IF(AV7>=0, "Yes", "Feb") -> Yes | AW6: =IF(AW7=0, "Yes", "Mar") -> Yes | AX6: =IF(AX7=0, "Yes", "Apr") -> Yes | AY6: =IF(AY7=0, "Yes", "May") -> Yes | AZ6: =IF(AZ7=0, "Yes", "Jun") -> Yes | BA6: =IF(BA7=0, "Yes", "Jul") -> Yes | BB6: =IF(BB7=0, "Yes", "Aug") -> Yes | BC6: =IF(BC7=0, "Yes", "Sep") -> Yes | BD6: =IF(BD7=0, "Yes", "Oct") -> Yes | BE6: =IF(BE7=0, "Yes", "Nov") -> Yes | BF6: =IF(BF7=0, "Yes", "Dec") -> Yes | BG6: =IF(BG7=0, "Yes", "Total") -> Yes | BI6: =IF(BJ7=0, "Yes", "Jan") -> Yes | BJ6: =IF(BJ7>=0, "Yes", "Feb") -> Yes | BK6: =IF(BK7=0, "Yes", "Mar") -> Yes | BL6: =IF(BL7=0, "Yes", "Apr") -> Yes | BM6: =IF(BM7=0, "Yes", "May") -> Yes | BN6: =IF(BN7=0, "Yes", "Jun") -> Yes | BO6: =IF(BO7=0, "Yes", "Jul") -> Yes | BP6: =IF(BP7=0, "Yes", "Aug") -> Yes | BQ6: =IF(BQ7=0, "Yes", "Sep") -> Yes | BR6: =IF(BR7=0, "Yes", "Oct") -> Yes | BS6: =IF(BS7=0, "Yes", "Nov") -> Yes | BT6: =IF(BT7=0, "Yes", "Dec") -> Yes | BU6: =IF(BU7=0, "Yes", "Total") -> Yes | BW6: =IF(BX7=0, "Yes", "Jan") -> Yes | BX6: =IF(BX7>=0, "Yes", "Feb") -> Yes | BY6: =IF(BY7=0, "Yes", "Mar") -> Yes | BZ6: =IF(BZ7=0, "Yes", "Apr") -> Yes | CA6: =IF(CA7=0, "Yes", "May") -> Yes | CB6: =IF(CB7=0, "Yes", "Jun") -> Yes | CC6: =IF(CC7=0, "Yes", "Jul") -> Yes | CD6: =IF(CD7=0, "Yes", "Aug") -> Yes | CE6: =IF(CE7=0, "Yes", "Sep") -> Yes | CF6: =IF(CF7=0, "Yes", "Oct") -> Yes | CG6: =IF(CG7=0, "Yes", "Nov") -> Yes | CH6: =IF(CH7=0, "Yes", "Dec") -> Yes | CI6: =IF(CI7=0, "Yes", "Total") -> Yes | CK6: =IF(CL7=0, "Yes", "Jan") -> Yes | CL6: =IF(CL7>=0, "Yes", "Feb") -> Yes | CM6: =IF(CM7=0, "Yes", "Mar") -> Yes | CN6: =IF(CN7=0, "Yes", "Apr") -> Yes | CO6: =IF(CO7=0, "Yes", "May") -> Yes | CP6: =IF(CP7=0, "Yes", "Jun") -> Yes | CQ6: =IF(CQ7=0, "Yes", "Jul") -> Yes | CR6: =IF(CR7=0, "Yes", "Aug") -> Yes | CS6: =IF(CS7=0, "Yes", "Sep") -> Yes | CT6: =IF(CT7=0, "Yes", "Oct") -> Yes | CU6: =IF(CU7=0, "Yes", "Nov") -> Yes | CV6: =IF(CV7=0, "Yes", "Dec") -> Yes | CW6: =IF(CW7=0, "Yes", "Total") -> Yes | CY6: =IF(CZ7=0, "Yes", "Jan") -> Yes | CZ6: =IF(CZ7>=0, "Yes", "Feb") -> Yes | DA6: =IF(DA7=0, "Yes", "Mar") -> Yes | DB6: =IF(DB7=0, "Yes", "Apr") -> Yes | DC6: =IF(DC7=0, "Yes", "May") -> Yes | DD6: =IF(DD7=0, "Yes", "Jun") -> Yes | DE6: =IF(DE7=0, "Yes", "Jul") -> Yes | DF6: =IF(DF7=0, "Yes", "Aug") -> Yes | DG6: =IF(DG7=0, "Yes", "Sep") -> Yes | DH6: =IF(DH7=0, "Yes", "Oct") -> Yes | DI6: =IF(DI7=0, "Yes", "Nov") -> Yes | DJ6: =IF(DJ7=0, "Yes", "Dec") -> Yes | DK6: =IF(DK7=0, "Yes", "Total") -> Yes | DM6: =IF(DN7=0, "Yes", "Jan") -> Yes | DN6: =IF(DN7>=0, "Yes", "Feb") -> Yes | DO6: =IF(DO7=0, "Yes", "Mar") -> Yes | DP6: =IF(DP7=0, "Yes", "Apr") -> Yes | DQ6: =IF(DQ7=0, "Yes", "May") -> Yes | DR6: =IF(DR7=0, "Yes", "Jun") -> Yes | DS6: =IF(DS7=0, "Yes", "Jul") -> Yes | DT6: =IF(DT7=0, "Yes", "Aug") -> Yes | DU6: =IF(DU7=0, "Yes", "Sep") -> Yes | DV6: =IF(DV7=0, "Yes", "Oct") -> Yes | DW6: =IF(DW7=0, "Yes", "Nov") -> Yes | DX6: =IF(DX7=0, "Yes", "Dec") -> Yes | DY6: =IF(DY7=0, "Yes", "Total") -> Yes
C7: To be allocated: | E7: =E20-(E33+E46) -> 0 | F7: =F20-(F33+F46) -> 0 | G7: =G20-(G33+G46) -> 0 | H7: =H20-(H33+H46) -> 0 | I7: =I20-(I33+I46) -> 0 | J7: =J20-(J33+J46) -> 0 | K7: =K20-(K33+K46) -> 0 | L7: =L20-(L33+L46) -> 0 | ... Q7: =Q20-(Q33+Q46) -> 0 | S7: =S20-(S33+S46) -> 0 | T7: =T20-(T33+T46) -> 0 | U7: =U20-(U33+U46) -> 0 | V7: =V20-(V33+V46) -> 0 | W7: =W20-(W33+W46) -> 0 | X7: =X20-(X33+X46) -> 0 | Y7: =Y20-(Y33+Y46) -> 0 | Z7: =Z20-(Z33+Z46) -> 0 | ... AE7: =AE20-(AE33+AE46) -> 0 | AG7: =AG20-(AG33+AG46) -> 0 | AH7: =AH20-(AH33+AH46) -> 0 | AI7: =AI20-(AI33+AI46) -> 0 | AJ7: =AJ20-(AJ33+AJ46) -> 0 | AK7: =AK20-(AK33+AK46) -> 0 | AL7: =AL20-(AL33+AL46) -> 0 | AM7: =AM20-(AM33+AM46) -> 0 | AN7: =AN20-(AN33+AN46) -> 0 | ... AS7: =AS20-(AS33+AS46) -> 0 | AU7: =AU20-(AU33+AU46) -> 0 | AV7: =AV20-(AV33+AV46) -> 0 | AW7: =AW20-(AW33+AW46) -> 0 | AX7: =AX20-(AX33+AX46) -> 0 | AY7: =AY20-(AY33+AY46) -> 0 | AZ7: =AZ20-(AZ33+AZ46) -> 0 | BA7: =BA20-(BA33+BA46) -> 0 | BB7: =BB20-(BB33+BB46) -> 0 | ... BG7: =BG20-(BG33+BG46) -> 0 | BI7: =BI20-(BI33+BI46) -> 0 | BJ7: =BJ20-(BJ33+BJ46) -> 0 | BK7: =BK20-(BK33+BK46) -> 0 | BL7: =BL20-(BL33+BL46) -> 0 | BM7: =BM20-(BM33+BM46) -> 0 | BN7: =BN20-(BN33+BN46) -> 0 | BO7: =BO20-(BO33+BO46) -> 0 | BP7: =BP20-(BP33+BP46) -> 0 | ... BU7: =BU20-(BU33+BU46) -> 0 | BW7: =BW20-(BW33+BW46) -> 0 | BX7: =BX20-(BX33+BX46) -> 0 | BY7: =BY20-(BY33+BY46) -> 0 | BZ7: =BZ20-(BZ33+BZ46) -> 0 | CA7: =CA20-(CA33+CA46) -> 0 | CB7: =CB20-(CB33+CB46) -> 0 | CC7: =CC20-(CC33+CC46) -> 0 | CD7: =CD20-(CD33+CD46) -> 0 | ... CI7: =CI20-(CI33+CI46) -> 0 | CK7: =CK20-(CK33+CK46) -> 0 | CL7: =CL20-(CL33+CL46) -> 0 | CM7: =CM20-(CM33+CM46) -> 0 | CN7: =CN20-(CN33+CN46) -> 0 | CO7: =CO20-(CO33+CO46) -> 0 | CP7: =CP20-(CP33+CP46) -> 0 | CQ7: =CQ20-(CQ33+CQ46) -> 0 | CR7: =CR20-(CR33+CR46) -> 0 | ... CW7: =CW20-(CW33+CW46) -> 0 | CY7: =CY20-(CY33+CY46) -> 0 | CZ7: =CZ20-(CZ33+CZ46) -> 0 | DA7: =DA20-(DA33+DA46) -> 0 | DB7: =DB20-(DB33+DB46) -> 0 | DC7: =DC20-(DC33+DC46) -> 0 | DD7: =DD20-(DD33+DD46) -> 0 | DE7: =DE20-(DE33+DE46) -> 0 | DF7: =DF20-(DF33+DF46) -> 0 | ... DK7: =DK20-(DK33+DK46) -> 0 | DM7: =DM20-(DM33+DM46) -> 0 | DN7: =DN20-(DN33+DN46) -> 0 | DO7: =DO20-(DO33+DO46) -> 0 | DP7: =DP20-(DP33+DP46) -> 0 | DQ7: =DQ20-(DQ33+DQ46) -> 0 | DR7: =DR20-(DR33+DR46) -> 0 | DS7: =DS20-(DS33+DS46) -> 0 | DT7: =DT20-(DT33+DT46) -> 0 | ... DY7: =DY20-(DY33+DY46) -> 0
C9: Income | E9: =DATE(E$5,1,1) -> 44562 | F9: =DATE(E$5,2,1) -> 44593 | G9: =DATE(E$5,3,1) -> 44621 | H9: =DATE(E$5,4,1) -> 44652 | I9: =DATE(E$5,5,1) -> 44682 | J9: =DATE(E$5,6,1) -> 44713 | K9: =DATE(E$5,7,1) -> 44743 | L9: =DATE(E$5,8,1) -> 44774 | M9: =DATE(E$5,9,1) -> 44805 | N9: =DATE(E$5,10,1) -> 44835 | O9: =DATE(E$5,11,1) -> 44866 | P9: =DATE(E$5,12,1) -> 44896 | Q9: =E5 -> 2022 | S9: =DATE(S$5,1,1) -> 44927 | T9: =DATE(S$5,2,1) -> 44958 | U9: =DATE(S$5,3,1) -> 44986 | V9: =DATE(S$5,4,1) -> 45017 | W9: =DATE(S$5,5,1) -> 45047 | X9: =DATE(S$5,6,1) -> 45078 | Y9: =DATE(S$5,7,1) -> 45108 | Z9: =DATE(S$5,8,1) -> 45139 | AA9: =DATE(S$5,9,1) -> 45170 | AB9: =DATE(S$5,10,1) -> 45200 | AC9: =DATE(S$5,11,1) -> 45231 | AD9: =DATE(S$5,12,1) -> 45261 | AE9: =Q9+1 -> 2023 | AG9: =DATE(AG$5,1,1) -> 45292 | AH9: =DATE(AG$5,2,1) -> 45323 | AI9: =DATE(AG$5,3,1) -> 45352 | AJ9: =DATE(AG$5,4,1) -> 45383 | AK9: =DATE(AG$5,5,1) -> 45413 | AL9: =DATE(AG$5,6,1) -> 45444 | AM9: =DATE(AG$5,7,1) -> 45474 | AN9: =DATE(AG$5,8,1) -> 45505 | AO9: =DATE(AG$5,9,1) -> 45536 | AP9: =DATE(AG$5,10,1) -> 45566 | AQ9: =DATE(AG$5,11,1) -> 45597 | AR9: =DATE(AG$5,12,1) -> 45627 | AS9: =AE9+1 -> 2024 | AU9: =DATE(AU$5,1,1) -> 45658 | AV9: =DATE(AU$5,2,1) -> 45689 | AW9: =DATE(AU$5,3,1) -> 45717 | AX9: =DATE(AU$5,4,1) -> 45748 | AY9: =DATE(AU$5,5,1) -> 45778 | AZ9: =DATE(AU$5,6,1) -> 45809 | BA9: =DATE(AU$5,7,1) -> 45839 | BB9: =DATE(AU$5,8,1) -> 45870 | BC9: =DATE(AU$5,9,1) -> 45901 | BD9: =DATE(AU$5,10,1) -> 45931 | BE9: =DATE(AU$5,11,1) -> 45962 | BF9: =DATE(AU$5,12,1) -> 45992 | BG9: =AS9+1 -> 2025 | BI9: =DATE(BI$5,1,1) -> 46023 | BJ9: =DATE(BI$5,2,1) -> 46054 | BK9: =DATE(BI$5,3,1) -> 46082 | BL9: =DATE(BI$5,4,1) -> 46113 | BM9: =DATE(BI$5,5,1) -> 46143 | BN9: =DATE(BI$5,6,1) -> 46174 | BO9: =DATE(BI$5,7,1) -> 46204 | BP9: =DATE(BI$5,8,1) -> 46235 | BQ9: =DATE(BI$5,9,1) -> 46266 | BR9: =DATE(BI$5,10,1) -> 46296 | BS9: =DATE(BI$5,11,1) -> 46327 | BT9: =DATE(BI$5,12,1) -> 46357 | BU9: =BG9+1 -> 2026 | BW9: =DATE(BW$5,1,1) -> 46388 | BX9: =DATE(BW$5,2,1) -> 46419 | BY9: =DATE(BW$5,3,1) -> 46447 | BZ9: =DATE(BW$5,4,1) -> 46478 | CA9: =DATE(BW$5,5,1) -> 46508 | CB9: =DATE(BW$5,6,1) -> 46539 | CC9: =DATE(BW$5,7,1) -> 46569 | CD9: =DATE(BW$5,8,1) -> 46600 | CE9: =DATE(BW$5,9,1) -> 46631 | CF9: =DATE(BW$5,10,1) -> 46661 | CG9: =DATE(BW$5,11,1) -> 46692 | CH9: =DATE(BW$5,12,1) -> 46722 | CI9: =BU9+1 -> 2027 | CK9: =DATE(CK$5,1,1) -> 46753 | CL9: =DATE(CK$5,2,1) -> 46784 | CM9: =DATE(CK$5,3,1) -> 46813 | CN9: =DATE(CK$5,4,1) -> 46844 | CO9: =DATE(CK$5,5,1) -> 46874 | CP9: =DATE(CK$5,6,1) -> 46905 | CQ9: =DATE(CK$5,7,1) -> 46935 | CR9: =DATE(CK$5,8,1) -> 46966 | CS9: =DATE(CK$5,9,1) -> 46997 | CT9: =DATE(CK$5,10,1) -> 47027 | CU9: =DATE(CK$5,11,1) -> 47058 | CV9: =DATE(CK$5,12,1) -> 47088 | CW9: =CI9+1 -> 2028 | CY9: =DATE(CY$5,1,1) -> 47119 | CZ9: =DATE(CY$5,2,1) -> 47150 | DA9: =DATE(CY$5,3,1) -> 47178 | DB9: =DATE(CY$5,4,1) -> 47209 | DC9: =DATE(CY$5,5,1) -> 47239 | DD9: =DATE(CY$5,6,1) -> 47270 | DE9: =DATE(CY$5,7,1) -> 47300 | DF9: =DATE(CY$5,8,1) -> 47331 | DG9: =DATE(CY$5,9,1) -> 47362 | DH9: =DATE(CY$5,10,1) -> 47392 | DI9: =DATE(CY$5,11,1) -> 47423 | DJ9: =DATE(CY$5,12,1) -> 47453 | DK9: =CW9+1 -> 2029 | DM9: =DATE(DM$5,1,1) -> 47484 | DN9: =DATE(DM$5,2,1) -> 47515 | DO9: =DATE(DM$5,3,1) -> 47543 | DP9: =DATE(DM$5,4,1) -> 47574 | DQ9: =DATE(DM$5,5,1) -> 47604 | DR9: =DATE(DM$5,6,1) -> 47635 | DS9: =DATE(DM$5,7,1) -> 47665 | DT9: =DATE(DM$5,8,1) -> 47696 | DU9: =DATE(DM$5,9,1) -> 47727 | DV9: =DATE(DM$5,10,1) -> 47757 | DW9: =DATE(DM$5,11,1) -> 47788 | DX9: =DATE(DM$5,12,1) -> 47818 | DY9: =DK9+1 -> 2030
C10: Employment(Net) | E10: 3500 | F10: 3500 | G10: 3500 | H10: 4500 | I10: 4500 | J10: 4500 | K10: 4500 | L10: 4500 | M10: 4500 | N10: 4500 | O10: 4500 | P10: 4500 | Q10: =SUM(E10:P10) -> 51000 | AE10: =SUM(S10:AD10) -> 0 | AS10: =SUM(AG10:AR10) -> 0 | BG10: =SUM(AU10:BF10) -> 0 | BU10: =SUM(BI10:BT10) -> 0 | CI10: =SUM(BW10:CH10) -> 0 | CW10: =SUM(CK10:CV10) -> 0 | DK10: =SUM(CY10:DJ10) -> 0 | DY10: =SUM(DM10:DX10) -> 0
C11: Side Hustles(net) | E11: 1000 | F11: 1000 | G11: 1000 | H11: 1000 | I11: 1000 | J11: 1000 | K11: 1000 | L11: 1000 | M11: 1000 | N11: 1000 | O11: 1000 | P11: 1000 | Q11: =SUM(E11:P11) -> 12000 | AE11: =SUM(S11:AD11) -> 0 | AS11: =SUM(AG11:AR11) -> 0 | BG11: =SUM(AU11:BF11) -> 0 | BU11: =SUM(BI11:BT11) -> 0 | CI11: =SUM(BW11:CH11) -> 0 | CW11: =SUM(CK11:CV11) -> 0 | DK11: =SUM(CY11:DJ11) -> 0 | DY11: =SUM(DM11:DX11) -> 0
C12: Dividends | E12: 150 | F12: 50 | G12: 100 | H12: 150 | I12: 50 | J12: 100 | K12: 150 | L12: 50 | M12: 100 | N12: 150 | O12: 50 | P12: 100 | Q12: =SUM(E12:P12) -> 1200 | AE12: =SUM(S12:AD12) -> 0 | AS12: =SUM(AG12:AR12) -> 0 | BG12: =SUM(AU12:BF12) -> 0 | BU12: =SUM(BI12:BT12) -> 0 | CI12: =SUM(BW12:CH12) -> 0 | CW12: =SUM(CK12:CV12) -> 0 | DK12: =SUM(CY12:DJ12) -> 0 | DY12: =SUM(DM12:DX12) -> 0
C13: Enter Income Category | Q13: =SUM(E13:P13) -> 0 | AE13: =SUM(S13:AD13) -> 0 | AS13: =SUM(AG13:AR13) -> 0 | BG13: =SUM(AU13:BF13) -> 0 | BU13: =SUM(BI13:BT13) -> 0 | CI13: =SUM(BW13:CH13) -> 0 | CW13: =SUM(CK13:CV13) -> 0 | DK13: =SUM(CY13:DJ13) -> 0 | DY13: =SUM(DM13:DX13) -> 0
C14: Enter Income Category | Q14: =SUM(E14:P14) -> 0 | AE14: =SUM(S14:AD14) -> 0 | AS14: =SUM(AG14:AR14) -> 0 | BG14: =SUM(AU14:BF14) -> 0 | BU14: =SUM(BI14:BT14) -> 0 | CI14: =SUM(BW14:CH14) -> 0 | CW14: =SUM(CK14:CV14) -> 0 | DK14: =SUM(CY14:DJ14) -> 0 | DY14: =SUM(DM14:DX14) -> 0
C15: Enter Income Category | Q15: =SUM(E15:P15) -> 0 | AE15: =SUM(S15:AD15) -> 0 | AS15: =SUM(AG15:AR15) -> 0 | BG15: =SUM(AU15:BF15) -> 0 | BU15: =SUM(BI15:BT15) -> 0 | CI15: =SUM(BW15:CH15) -> 0 | CW15: =SUM(CK15:CV15) -> 0 | DK15: =SUM(CY15:DJ15) -> 0 | DY15: =SUM(DM15:DX15) -> 0
C16: Enter Income Category | Q16: =SUM(E16:P16) -> 0 | AE16: =SUM(S16:AD16) -> 0 | AS16: =SUM(AG16:AR16) -> 0 | BG16: =SUM(AU16:BF16) -> 0 | BU16: =SUM(BI16:BT16) -> 0 | CI16: =SUM(BW16:CH16) -> 0 | CW16: =SUM(CK16:CV16) -> 0 | DK16: =SUM(CY16:DJ16) -> 0 | DY16: =SUM(DM16:DX16) -> 0
C17: Enter Income Category | Q17: =SUM(E17:P17) -> 0 | AE17: =SUM(S17:AD17) -> 0 | AS17: =SUM(AG17:AR17) -> 0 | BG17: =SUM(AU17:BF17) -> 0 | BU17: =SUM(BI17:BT17) -> 0 | CI17: =SUM(BW17:CH17) -> 0 | CW17: =SUM(CK17:CV17) -> 0 | DK17: =SUM(CY17:DJ17) -> 0 | DY17: =SUM(DM17:DX17) -> 0
C18: Enter Income Category | Q18: =SUM(E18:P18) -> 0 | AE18: =SUM(S18:AD18) -> 0 | AS18: =SUM(AG18:AR18) -> 0 | BG18: =SUM(AU18:BF18) -> 0 | BU18: =SUM(BI18:BT18) -> 0 | CI18: =SUM(BW18:CH18) -> 0 | CW18: =SUM(CK18:CV18) -> 0 | DK18: =SUM(CY18:DJ18) -> 0 | DY18: =SUM(DM18:DX18) -> 0
C19: Enter Income Category | Q19: =SUM(E19:P19) -> 0 | AE19: =SUM(S19:AD19) -> 0 | AS19: =SUM(AG19:AR19) -> 0 | BG19: =SUM(AU19:BF19) -> 0 | BU19: =SUM(BI19:BT19) -> 0 | CI19: =SUM(BW19:CH19) -> 0 | CW19: =SUM(CK19:CV19) -> 0 | DK19: =SUM(CY19:DJ19) -> 0 | DY19: =SUM(DM19:DX19) -> 0
C20: Total | E20: {=SUM(INDIRECT(ADDRESS(income_min_row,COLUMN()) & ":" & ADDRESS(income_max_row, COLUMN())))} -> 4650 | F20: {=SUM(INDIRECT(ADDRESS(income_min_row,COLUMN()) & ":" & ADDRESS(income_max_row, COLUMN())))} -> 4550 | G20: {=SUM(INDIRECT(ADDRESS(income_min_row,COLUMN()) & ":" & ADDRESS(income_max_row, COLUMN())))} -> 4600 | H20: {=SUM(INDIRECT(ADDRESS(income_min_row,COLUMN()) & ":" & ADDRESS(income_max_row, COLUMN())))} -> 5650 | I20: {=SUM(INDIRECT(ADDRESS(income_min_row,COLUMN()) & ":" & ADDRESS(income_max_row, COLUMN())))} -> 5550 | J20: {=SUM(INDIRECT(ADDRESS(income_min_row,COLUMN()) & ":" & ADDRESS(income_max_row, COLUMN())))} -> 5600 | K20: {=SUM(INDIRECT(ADDRESS(income_min_row,COLUMN()) & ":" & ADDRESS(income_max_row, COLUMN())))} -> 5650 | L20: {=SUM(INDIRECT(ADDRESS(income_min_row,COLUMN()) & ":" & ADDRESS(income_max_row, COLUMN())))} -> 5550 | ... P20: {=SUM(INDIRECT(ADDRESS(income_min_row,COLUMN()) & ":" & ADDRESS(income_max_row, COLUMN())))} -> 5600 | Q20: =SUM(E20:P20) -> 64200 | S20: {=SUM(INDIRECT(ADDRESS(income_min_row,COLUMN()) & ":" & ADDRESS(income_max_row, COLUMN())))} -> 0 | T20: {=SUM(INDIRECT(ADDRESS(income_min_row,COLUMN()) & ":" & ADDRESS(income_max_row, COLUMN())))} -> 0 | U20: {=SUM(INDIRECT(ADDRESS(income_min_row,COLUMN()) & ":" & ADDRESS(income_max_row, COLUMN())))} -> 0 | V20: {=SUM(INDIRECT(ADDRESS(income_min_row,COLUMN()) & ":" & ADDRESS(income_max_row, COLUMN())))} -> 0 | X20: {=SUM(INDIRECT(ADDRESS(income_min_row,COLUMN()) & ":" & ADDRESS(income_max_row, COLUMN())))} -> 0 | Y20: {=SUM(INDIRECT(ADDRESS(income_min_row,COLUMN()) & ":" & ADDRESS(income_max_row, COLUMN())))} -> 0 | Z20: {=SUM(INDIRECT(ADDRESS(income_min_row,COLUMN()) & ":" & ADDRESS(income_max_row, COLUMN())))} -> 0 | AA20: {=SUM(INDIRECT(ADDRESS(income_min_row,COLUMN()) & ":" & ADDRESS(income_max_row, COLUMN())))} -> 0 | AB20: {=SUM(INDIRECT(ADDRESS(income_min_row,COLUMN()) & ":" & ADDRESS(income_max_row, COLUMN())))} -> 0 | AC20: {=SUM(INDIRECT(ADDRESS(income_min_row,COLUMN()) & ":" & ADDRESS(income_max_row, COLUMN())))} -> 0 | AD20: {=SUM(INDIRECT(ADDRESS(income_min_row,COLUMN()) & ":" & ADDRESS(income_max_row, COLUMN())))} -> 0 | AE20: =SUM(S20:AD20) -> 0 | AG20: {=SUM(INDIRECT(ADDRESS(income_min_row,COLUMN()) & ":" & ADDRESS(income_max_row, COLUMN())))} -> 0 | AH20: {=SUM(INDIRECT(ADDRESS(income_min_row,COLUMN()) & ":" & ADDRESS(income_max_row, COLUMN())))} -> 0 | AI20: {=SUM(INDIRECT(ADDRESS(income_min_row,COLUMN()) & ":" & ADDRESS(income_max_row, COLUMN())))} -> 0 | AJ20: {=SUM(INDIRECT(ADDRESS(income_min_row,COLUMN()) & ":" & ADDRESS(income_max_row, COLUMN())))} -> 0 | AL20: {=SUM(INDIRECT(ADDRESS(income_min_row,COLUMN()) & ":" & ADDRESS(income_max_row, COLUMN())))} -> 0 | AM20: {=SUM(INDIRECT(ADDRESS(income_min_row,COLUMN()) & ":" & ADDRESS(income_max_row, COLUMN())))} -> 0 | AN20: {=SUM(INDIRECT(ADDRESS(income_min_row,COLUMN()) & ":" & ADDRESS(income_max_row, COLUMN())))} -> 0 | AO20: {=SUM(INDIRECT(ADDRESS(income_min_row,COLUMN()) & ":" & ADDRESS(income_max_row, COLUMN())))} -> 0 | AP20: {=SUM(INDIRECT(ADDRESS(income_min_row,COLUMN()) & ":" & ADDRESS(income_max_row, COLUMN())))} -> 0 | AQ20: {=SUM(INDIRECT(ADDRESS(income_min_row,COLUMN()) & ":" & ADDRESS(income_max_row, COLUMN())))} -> 0 | AR20: {=SUM(INDIRECT(ADDRESS(income_min_row,COLUMN()) & ":" & ADDRESS(income_max_row, COLUMN())))} -> 0 | AS20: =SUM(AG20:AR20) -> 0 | AU20: {=SUM(INDIRECT(ADDRESS(income_min_row,COLUMN()) & ":" & ADDRESS(income_max_row, COLUMN())))} -> 0 | AV20: {=SUM(INDIRECT(ADDRESS(income_min_row,COLUMN()) & ":" & ADDRESS(income_max_row, COLUMN())))} -> 0 | AW20: {=SUM(INDIRECT(ADDRESS(income_min_row,COLUMN()) & ":" & ADDRESS(income_max_row, COLUMN())))} -> 0 | AX20: {=SUM(INDIRECT(ADDRESS(income_min_row,COLUMN()) & ":" & ADDRESS(income_max_row, COLUMN())))} -> 0 | AZ20: {=SUM(INDIRECT(ADDRESS(income_min_row,COLUMN()) & ":" & ADDRESS(income_max_row, COLUMN())))} -> 0 | BA20: {=SUM(INDIRECT(ADDRESS(income_min_row,COLUMN()) & ":" & ADDRESS(income_max_row, COLUMN())))} -> 0 | BB20: {=SUM(INDIRECT(ADDRESS(income_min_row,COLUMN()) & ":" & ADDRESS(income_max_row, COLUMN())))} -> 0 | BC20: {=SUM(INDIRECT(ADDRESS(income_min_row,COLUMN()) & ":" & ADDRESS(income_max_row, COLUMN())))} -> 0 | BD20: {=SUM(INDIRECT(ADDRESS(income_min_row,COLUMN()) & ":" & ADDRESS(income_max_row, COLUMN())))} -> 0 | BE20: {=SUM(INDIRECT(ADDRESS(income_min_row,COLUMN()) & ":" & ADDRESS(income_max_row, COLUMN())))} -> 0 | BF20: {=SUM(INDIRECT(ADDRESS(income_min_row,COLUMN()) & ":" & ADDRESS(income_max_row, COLUMN())))} -> 0 | BG20: =SUM(AU20:BF20) -> 0 | BI20: {=SUM(INDIRECT(ADDRESS(income_min_row,COLUMN()) & ":" & ADDRESS(income_max_row, COLUMN())))} -> 0 | BJ20: {=SUM(INDIRECT(ADDRESS(income_min_row,COLUMN()) & ":" & ADDRESS(income_max_row, COLUMN())))} -> 0 | BK20: {=SUM(INDIRECT(ADDRESS(income_min_row,COLUMN()) & ":" & ADDRESS(income_max_row, COLUMN())))} -> 0 | BL20: {=SUM(INDIRECT(ADDRESS(income_min_row,COLUMN()) & ":" & ADDRESS(income_max_row, COLUMN())))} -> 0 | BN20: {=SUM(INDIRECT(ADDRESS(income_min_row,COLUMN()) & ":" & ADDRESS(income_max_row, COLUMN())))} -> 0 | BO20: {=SUM(INDIRECT(ADDRESS(income_min_row,COLUMN()) & ":" & ADDRESS(income_max_row, COLUMN())))} -> 0 | BP20: {=SUM(INDIRECT(ADDRESS(income_min_row,COLUMN()) & ":" & ADDRESS(income_max_row, COLUMN())))} -> 0 | BQ20: {=SUM(INDIRECT(ADDRESS(income_min_row,COLUMN()) & ":" & ADDRESS(income_max_row, COLUMN())))} -> 0 | BR20: {=SUM(INDIRECT(ADDRESS(income_min_row,COLUMN()) & ":" & ADDRESS(income_max_row, COLUMN())))} -> 0 | BS20: {=SUM(INDIRECT(ADDRESS(income_min_row,COLUMN()) & ":" & ADDRESS(income_max_row, COLUMN())))} -> 0 | BT20: {=SUM(INDIRECT(ADDRESS(income_min_row,COLUMN()) & ":" & ADDRESS(income_max_row, COLUMN())))} -> 0 | BU20: =SUM(BI20:BT20) -> 0 | BW20: {=SUM(INDIRECT(ADDRESS(income_min_row,COLUMN()) & ":" & ADDRESS(income_max_row, COLUMN())))} -> 0 | BX20: {=SUM(INDIRECT(ADDRESS(income_min_row,COLUMN()) & ":" & ADDRESS(income_max_row, COLUMN())))} -> 0 | BY20: {=SUM(INDIRECT(ADDRESS(income_min_row,COLUMN()) & ":" & ADDRESS(income_max_row, COLUMN())))} -> 0 | BZ20: {=SUM(INDIRECT(ADDRESS(income_min_row,COLUMN()) & ":" & ADDRESS(income_max_row, COLUMN())))} -> 0 | CB20: {=SUM(INDIRECT(ADDRESS(income_min_row,COLUMN()) & ":" & ADDRESS(income_max_row, COLUMN())))} -> 0 | CC20: {=SUM(INDIRECT(ADDRESS(income_min_row,COLUMN()) & ":" & ADDRESS(income_max_row, COLUMN())))} -> 0 | CD20: {=SUM(INDIRECT(ADDRESS(income_min_row,COLUMN()) & ":" & ADDRESS(income_max_row, COLUMN())))} -> 0 | CE20: {=SUM(INDIRECT(ADDRESS(income_min_row,COLUMN()) & ":" & ADDRESS(income_max_row, COLUMN())))} -> 0 | CF20: {=SUM(INDIRECT(ADDRESS(income_min_row,COLUMN()) & ":" & ADDRESS(income_max_row, COLUMN())))} -> 0 | CG20: {=SUM(INDIRECT(ADDRESS(income_min_row,COLUMN()) & ":" & ADDRESS(income_max_row, COLUMN())))} -> 0 | CH20: {=SUM(INDIRECT(ADDRESS(income_min_row,COLUMN()) & ":" & ADDRESS(income_max_row, COLUMN())))} -> 0 | CI20: =SUM(BW20:CH20) -> 0 | CK20: {=SUM(INDIRECT(ADDRESS(income_min_row,COLUMN()) & ":" & ADDRESS(income_max_row, COLUMN())))} -> 0 | CL20: {=SUM(INDIRECT(ADDRESS(income_min_row,COLUMN()) & ":" & ADDRESS(income_max_row, COLUMN())))} -> 0 | CM20: {=SUM(INDIRECT(ADDRESS(income_min_row,COLUMN()) & ":" & ADDRESS(income_max_row, COLUMN())))} -> 0 | CN20: {=SUM(INDIRECT(ADDRESS(income_min_row,COLUMN()) & ":" & ADDRESS(income_max_row, COLUMN())))} -> 0 | CP20: {=SUM(INDIRECT(ADDRESS(income_min_row,COLUMN()) & ":" & ADDRESS(income_max_row, COLUMN())))} -> 0 | CQ20: {=SUM(INDIRECT(ADDRESS(income_min_row,COLUMN()) & ":" & ADDRESS(income_max_row, COLUMN())))} -> 0 | CR20: {=SUM(INDIRECT(ADDRESS(income_min_row,COLUMN()) & ":" & ADDRESS(income_max_row, COLUMN())))} -> 0 | CS20: {=SUM(INDIRECT(ADDRESS(income_min_row,COLUMN()) & ":" & ADDRESS(income_max_row, COLUMN())))} -> 0 | CT20: {=SUM(INDIRECT(ADDRESS(income_min_row,COLUMN()) & ":" & ADDRESS(income_max_row, COLUMN())))} -> 0 | CU20: {=SUM(INDIRECT(ADDRESS(income_min_row,COLUMN()) & ":" & ADDRESS(income_max_row, COLUMN())))} -> 0 | CV20: {=SUM(INDIRECT(ADDRESS(income_min_row,COLUMN()) & ":" & ADDRESS(income_max_row, COLUMN())))} -> 0 | CW20: =SUM(CK20:CV20) -> 0 | CY20: {=SUM(INDIRECT(ADDRESS(income_min_row,COLUMN()) & ":" & ADDRESS(income_max_row, COLUMN())))} -> 0 | CZ20: {=SUM(INDIRECT(ADDRESS(income_min_row,COLUMN()) & ":" & ADDRESS(income_max_row, COLUMN())))} -> 0 | DA20: {=SUM(INDIRECT(ADDRESS(income_min_row,COLUMN()) & ":" & ADDRESS(income_max_row, COLUMN())))} -> 0 | DB20: {=SUM(INDIRECT(ADDRESS(income_min_row,COLUMN()) & ":" & ADDRESS(income_max_row, COLUMN())))} -> 0 | DD20: {=SUM(INDIRECT(ADDRESS(income_min_row,COLUMN()) & ":" & ADDRESS(income_max_row, COLUMN())))} -> 0 | DE20: {=SUM(INDIRECT(ADDRESS(income_min_row,COLUMN()) & ":" & ADDRESS(income_max_row, COLUMN())))} -> 0 | DF20: {=SUM(INDIRECT(ADDRESS(income_min_row,COLUMN()) & ":" & ADDRESS(income_max_row, COLUMN())))} -> 0 | DG20: {=SUM(INDIRECT(ADDRESS(income_min_row,COLUMN()) & ":" & ADDRESS(income_max_row, COLUMN())))} -> 0 | DH20: {=SUM(INDIRECT(ADDRESS(income_min_row,COLUMN()) & ":" & ADDRESS(income_max_row, COLUMN())))} -> 0 | DI20: {=SUM(INDIRECT(ADDRESS(income_min_row,COLUMN()) & ":" & ADDRESS(income_max_row, COLUMN())))} -> 0 | DJ20: {=SUM(INDIRECT(ADDRESS(income_min_row,COLUMN()) & ":" & ADDRESS(income_max_row, COLUMN())))} -> 0 | DK20: =SUM(CY20:DJ20) -> 0 | DM20: {=SUM(INDIRECT(ADDRESS(income_min_row,COLUMN()) & ":" & ADDRESS(income_max_row, COLUMN())))} -> 0 | DN20: {=SUM(INDIRECT(ADDRESS(income_min_row,COLUMN()) & ":" & ADDRESS(income_max_row, COLUMN())))} -> 0 | DO20: {=SUM(INDIRECT(ADDRESS(income_min_row,COLUMN()) & ":" & ADDRESS(income_max_row, COLUMN())))} -> 0 | DP20: {=SUM(INDIRECT(ADDRESS(income_min_row,COLUMN()) & ":" & ADDRESS(income_max_row, COLUMN())))} -> 0 | DR20: {=SUM(INDIRECT(ADDRESS(income_min_row,COLUMN()) & ":" & ADDRESS(income_max_row, COLUMN())))} -> 0 | DS20: {=SUM(INDIRECT(ADDRESS(income_min_row,COLUMN()) & ":" & ADDRESS(income_max_row, COLUMN())))} -> 0 | DT20: {=SUM(INDIRECT(ADDRESS(income_min_row,COLUMN()) & ":" & ADDRESS(income_max_row, COLUMN())))} -> 0 | DU20: {=SUM(INDIRECT(ADDRESS(income_min_row,COLUMN()) & ":" & ADDRESS(income_max_row, COLUMN())))} -> 0 | DV20: {=SUM(INDIRECT(ADDRESS(income_min_row,COLUMN()) & ":" & ADDRESS(income_max_row, COLUMN())))} -> 0 | DW20: {=SUM(INDIRECT(ADDRESS(income_min_row,COLUMN()) & ":" & ADDRESS(income_max_row, COLUMN())))} -> 0 | DX20: {=SUM(INDIRECT(ADDRESS(income_min_row,COLUMN()) & ":" & ADDRESS(income_max_row, COLUMN())))} -> 0 | DY20: =SUM(DM20:DX20) -> 0
C22: Expenses | E22: =DATE(E$5,1,1) -> 44562 | F22: =DATE(E$5,2,1) -> 44593 | G22: =DATE(E$5,3,1) -> 44621 | H22: =DATE(E$5,4,1) -> 44652 | I22: =DATE(E$5,5,1) -> 44682 | J22: =DATE(E$5,6,1) -> 44713 | K22: =DATE(E$5,7,1) -> 44743 | L22: =DATE(E$5,8,1) -> 44774 | M22: =DATE(E$5,9,1) -> 44805 | N22: =DATE(E$5,10,1) -> 44835 | O22: =DATE(E$5,11,1) -> 44866 | P22: =DATE(E$5,12,1) -> 44896 | Q22: 2022 | S22: =DATE(S$5,1,1) -> 44927 | T22: =DATE(S$5,2,1) -> 44958 | U22: =DATE(S$5,3,1) -> 44986 | V22: =DATE(S$5,4,1) -> 45017 | W22: =DATE(S$5,5,1) -> 45047 | X22: =DATE(S$5,6,1) -> 45078 | Y22: =DATE(S$5,7,1) -> 45108 | Z22: =DATE(S$5,8,1) -> 45139 | AA22: =DATE(S$5,9,1) -> 45170 | AB22: =DATE(S$5,10,1) -> 45200 | AC22: =DATE(S$5,11,1) -> 45231 | AD22: =DATE(S$5,12,1) -> 45261 | AE22: =Q22+1 -> 2023 | AG22: =DATE(AG$5,1,1) -> 45292 | AH22: =DATE(AG$5,2,1) -> 45323 | AI22: =DATE(AG$5,3,1) -> 45352 | AJ22: =DATE(AG$5,4,1) -> 45383 | AK22: =DATE(AG$5,5,1) -> 45413 | AL22: =DATE(AG$5,6,1) -> 45444 | AM22: =DATE(AG$5,7,1) -> 45474 | AN22: =DATE(AG$5,8,1) -> 45505 | AO22: =DATE(AG$5,9,1) -> 45536 | AP22: =DATE(AG$5,10,1) -> 45566 | AQ22: =DATE(AG$5,11,1) -> 45597 | AR22: =DATE(AG$5,12,1) -> 45627 | AS22: =AE22+1 -> 2024 | AU22: =DATE(AU$5,1,1) -> 45658 | AV22: =DATE(AU$5,2,1) -> 45689 | AW22: =DATE(AU$5,3,1) -> 45717 | AX22: =DATE(AU$5,4,1) -> 45748 | AY22: =DATE(AU$5,5,1) -> 45778 | AZ22: =DATE(AU$5,6,1) -> 45809 | BA22: =DATE(AU$5,7,1) -> 45839 | BB22: =DATE(AU$5,8,1) -> 45870 | BC22: =DATE(AU$5,9,1) -> 45901 | BD22: =DATE(AU$5,10,1) -> 45931 | BE22: =DATE(AU$5,11,1) -> 45962 | BF22: =DATE(AU$5,12,1) -> 45992 | BG22: =AS22+1 -> 2025 | BI22: =DATE(BI$5,1,1) -> 46023 | BJ22: =DATE(BI$5,2,1) -> 46054 | BK22: =DATE(BI$5,3,1) -> 46082 | BL22: =DATE(BI$5,4,1) -> 46113 | BM22: =DATE(BI$5,5,1) -> 46143 | BN22: =DATE(BI$5,6,1) -> 46174 | BO22: =DATE(BI$5,7,1) -> 46204 | BP22: =DATE(BI$5,8,1) -> 46235 | BQ22: =DATE(BI$5,9,1) -> 46266 | BR22: =DATE(BI$5,10,1) -> 46296 | BS22: =DATE(BI$5,11,1) -> 46327 | BT22: =DATE(BI$5,12,1) -> 46357 | BU22: =BG22+1 -> 2026 | BW22: =DATE(BW$5,1,1) -> 46388 | BX22: =DATE(BW$5,2,1) -> 46419 | BY22: =DATE(BW$5,3,1) -> 46447 | BZ22: =DATE(BW$5,4,1) -> 46478 | CA22: =DATE(BW$5,5,1) -> 46508 | CB22: =DATE(BW$5,6,1) -> 46539 | CC22: =DATE(BW$5,7,1) -> 46569 | CD22: =DATE(BW$5,8,1) -> 46600 | CE22: =DATE(BW$5,9,1) -> 46631 | CF22: =DATE(BW$5,10,1) -> 46661 | CG22: =DATE(BW$5,11,1) -> 46692 | CH22: =DATE(BW$5,12,1) -> 46722 | CI22: =BU22+1 -> 2027 | CK22: =DATE(CK$5,1,1) -> 46753 | CL22: =DATE(CK$5,2,1) -> 46784 | CM22: =DATE(CK$5,3,1) -> 46813 | CN22: =DATE(CK$5,4,1) -> 46844 | CO22: =DATE(CK$5,5,1) -> 46874 | CP22: =DATE(CK$5,6,1) -> 46905 | CQ22: =DATE(CK$5,7,1) -> 46935 | CR22: =DATE(CK$5,8,1) -> 46966 | CS22: =DATE(CK$5,9,1) -> 46997 | CT22: =DATE(CK$5,10,1) -> 47027 | CU22: =DATE(CK$5,11,1) -> 47058 | CV22: =DATE(CK$5,12,1) -> 47088 | CW22: =CI22+1 -> 2028 | CY22: =DATE(CY$5,1,1) -> 47119 | CZ22: =DATE(CY$5,2,1) -> 47150 | DA22: =DATE(CY$5,3,1) -> 47178 | DB22: =DATE(CY$5,4,1) -> 47209 | DC22: =DATE(CY$5,5,1) -> 47239 | DD22: =DATE(CY$5,6,1) -> 47270 | DE22: =DATE(CY$5,7,1) -> 47300 | DF22: =DATE(CY$5,8,1) -> 47331 | DG22: =DATE(CY$5,9,1) -> 47362 | DH22: =DATE(CY$5,10,1) -> 47392 | DI22: =DATE(CY$5,11,1) -> 47423 | DJ22: =DATE(CY$5,12,1) -> 47453 | DK22: =CW22+1 -> 2029 | DM22: =DATE(DM$5,1,1) -> 47484 | DN22: =DATE(DM$5,2,1) -> 47515 | DO22: =DATE(DM$5,3,1) -> 47543 | DP22: =DATE(DM$5,4,1) -> 47574 | DQ22: =DATE(DM$5,5,1) -> 47604 | DR22: =DATE(DM$5,6,1) -> 47635 | DS22: =DATE(DM$5,7,1) -> 47665 | DT22: =DATE(DM$5,8,1) -> 47696 | DU22: =DATE(DM$5,9,1) -> 47727 | DV22: =DATE(DM$5,10,1) -> 47757 | DW22: =DATE(DM$5,11,1) -> 47788 | DX22: =DATE(DM$5,12,1) -> 47818 | DY22: =DK22+1 -> 2030
C23: Housing | E23: 1200 | F23: 1200 | G23: 1200 | H23: 1200 | I23: 1200 | J23: 1200 | K23: 1200 | L23: 1200 | M23: 1200 | N23: 1200 | O23: 1200 | P23: 1200 | Q23: =SUM(E23:P23) -> 14400 | AE23: =SUM(S23:AD23) -> 0 | AS23: =SUM(AG23:AR23) -> 0 | BG23: =SUM(AU23:BF23) -> 0 | BU23: =SUM(BI23:BT23) -> 0 | CI23: =SUM(BW23:CH23) -> 0 | CW23: =SUM(CK23:CV23) -> 0 | DK23: =SUM(CY23:DJ23) -> 0 | DY23: =SUM(DM23:DX23) -> 0
C24: Utilities | E24: 300 | F24: 300 | G24: 300 | H24: 300 | I24: 300 | J24: 300 | K24: 300 | L24: 300 | M24: 300 | N24: 300 | O24: 300 | P24: 300 | Q24: =SUM(E24:P24) -> 3600 | AE24: =SUM(S24:AD24) -> 0 | AS24: =SUM(AG24:AR24) -> 0 | BG24: =SUM(AU24:BF24) -> 0 | BU24: =SUM(BI24:BT24) -> 0 | CI24: =SUM(BW24:CH24) -> 0 | CW24: =SUM(CK24:CV24) -> 0 | DK24: =SUM(CY24:DJ24) -> 0 | DY24: =SUM(DM24:DX24) -> 0
C25: Groceries | E25: 350 | F25: 350 | G25: 350 | H25: 350 | I25: 350 | J25: 350 | K25: 350 | L25: 350 | M25: 350 | N25: 350 | O25: 350 | P25: 350 | Q25: =SUM(E25:P25) -> 4200 | AE25: =SUM(S25:AD25) -> 0 | AS25: =SUM(AG25:AR25) -> 0 | BG25: =SUM(AU25:BF25) -> 0 | BU25: =SUM(BI25:BT25) -> 0 | CI25: =SUM(BW25:CH25) -> 0 | CW25: =SUM(CK25:CV25) -> 0 | DK25: =SUM(CY25:DJ25) -> 0 | DY25: =SUM(DM25:DX25) -> 0
C26: Transport | E26: 300 | F26: 300 | G26: 300 | H26: 300 | I26: 300 | J26: 300 | K26: 300 | L26: 300 | M26: 300 | N26: 300 | O26: 300 | P26: 300 | Q26: =SUM(E26:P26) -> 3600 | AE26: =SUM(S26:AD26) -> 0 | AS26: =SUM(AG26:AR26) -> 0 | BG26: =SUM(AU26:BF26) -> 0 | BU26: =SUM(BI26:BT26) -> 0 | CI26: =SUM(BW26:CH26) -> 0 | CW26: =SUM(CK26:CV26) -> 0 | DK26: =SUM(CY26:DJ26) -> 0 | DY26: =SUM(DM26:DX26) -> 0
C27: Insurance | E27: 0 | F27: 0 | G27: 150 | H27: 0 | I27: 0 | J27: 150 | K27: 0 | L27: 0 | M27: 150 | N27: 0 | O27: 0 | P27: 150 | Q27: =SUM(E27:P27) -> 600 | AE27: =SUM(S27:AD27) -> 0 | AS27: =SUM(AG27:AR27) -> 0 | BG27: =SUM(AU27:BF27) -> 0 | BU27: =SUM(BI27:BT27) -> 0 | CI27: =SUM(BW27:CH27) -> 0 | CW27: =SUM(CK27:CV27) -> 0 | DK27: =SUM(CY27:DJ27) -> 0 | DY27: =SUM(DM27:DX27) -> 0
C28: Clothing | E28: 200 | F28: 200 | G28: 200 | H28: 200 | I28: 200 | J28: 200 | K28: 200 | L28: 200 | M28: 200 | N28: 200 | O28: 200 | P28: 200 | Q28: =SUM(E28:P28) -> 2400 | AE28: =SUM(S28:AD28) -> 0 | AS28: =SUM(AG28:AR28) -> 0 | BG28: =SUM(AU28:BF28) -> 0 | BU28: =SUM(BI28:BT28) -> 0 | CI28: =SUM(BW28:CH28) -> 0 | CW28: =SUM(CK28:CV28) -> 0 | DK28: =SUM(CY28:DJ28) -> 0 | DY28: =SUM(DM28:DX28) -> 0
C29: Body care | E29: 200 | F29: 200 | G29: 200 | H29: 200 | I29: 200 | J29: 200 | K29: 200 | L29: 200 | M29: 200 | N29: 200 | O29: 200 | P29: 200 | Q29: =SUM(E29:P29) -> 2400 | AE29: =SUM(S29:AD29) -> 0 | AS29: =SUM(AG29:AR29) -> 0 | BG29: =SUM(AU29:BF29) -> 0 | BU29: =SUM(BI29:BT29) -> 0 | CI29: =SUM(BW29:CH29) -> 0 | CW29: =SUM(CK29:CV29) -> 0 | DK29: =SUM(CY29:DJ29) -> 0 | DY29: =SUM(DM29:DX29) -> 0
C30: Media | E30: 50 | F30: 50 | G30: 50 | H30: 50 | I30: 50 | J30: 50 | K30: 50 | L30: 50 | M30: 50 | N30: 50 | O30: 50 | P30: 50 | Q30: =SUM(E30:P30) -> 600 | AE30: =SUM(S30:AD30) -> 0 | AS30: =SUM(AG30:AR30) -> 0 | BG30: =SUM(AU30:BF30) -> 0 | BU30: =SUM(BI30:BT30) -> 0 | CI30: =SUM(BW30:CH30) -> 0 | CW30: =SUM(CK30:CV30) -> 0 | DK30: =SUM(CY30:DJ30) -> 0 | DY30: =SUM(DM30:DX30) -> 0
C31: Fun&Vacation | E31: 300 | F31: 300 | G31: 300 | H31: 1200 | I31: 300 | J31: 300 | K31: 300 | L31: 1500 | M31: 300 | N31: 300 | O31: 300 | P31: 600 | Q31: =SUM(E31:P31) -> 6000 | AE31: =SUM(S31:AD31) -> 0 | AS31: =SUM(AG31:AR31) -> 0 | BG31: =SUM(AU31:BF31) -> 0 | BU31: =SUM(BI31:BT31) -> 0 | CI31: =SUM(BW31:CH31) -> 0 | CW31: =SUM(CK31:CV31) -> 0 | DK31: =SUM(CY31:DJ31) -> 0 | DY31: =SUM(DM31:DX31) -> 0
C32: Enter Income Category | Q32: =SUM(E32:P32) -> 0 | AE32: =SUM(S32:AD32) -> 0 | AS32: =SUM(AG32:AR32) -> 0 | BG32: =SUM(AU32:BF32) -> 0 | BU32: =SUM(BI32:BT32) -> 0 | CI32: =SUM(BW32:CH32) -> 0 | CW32: =SUM(CK32:CV32) -> 0 | DK32: =SUM(CY32:DJ32) -> 0 | DY32: =SUM(DM32:DX32) -> 0
C33: Total | E33: {=SUM(INDIRECT(ADDRESS(expenses_min_row,COLUMN()) & ":" & ADDRESS(expenses_max_row, COLUMN())))} -> 2900 | F33: {=SUM(INDIRECT(ADDRESS(expenses_min_row,COLUMN()) & ":" & ADDRESS(expenses_max_row, COLUMN())))} -> 2900 | G33: {=SUM(INDIRECT(ADDRESS(expenses_min_row,COLUMN()) & ":" & ADDRESS(expenses_max_row, COLUMN())))} -> 3050 | H33: {=SUM(INDIRECT(ADDRESS(expenses_min_row,COLUMN()) & ":" & ADDRESS(expenses_max_row, COLUMN())))} -> 3800 | I33: {=SUM(INDIRECT(ADDRESS(expenses_min_row,COLUMN()) & ":" & ADDRESS(expenses_max_row, COLUMN())))} -> 2900 | J33: {=SUM(INDIRECT(ADDRESS(expenses_min_row,COLUMN()) & ":" & ADDRESS(expenses_max_row, COLUMN())))} -> 3050 | K33: {=SUM(INDIRECT(ADDRESS(expenses_min_row,COLUMN()) & ":" & ADDRESS(expenses_max_row, COLUMN())))} -> 2900 | L33: {=SUM(INDIRECT(ADDRESS(expenses_min_row,COLUMN()) & ":" & ADDRESS(expenses_max_row, COLUMN())))} -> 4100 | ... P33: {=SUM(INDIRECT(ADDRESS(expenses_min_row,COLUMN()) & ":" & ADDRESS(expenses_max_row, COLUMN())))} -> 3350 | Q33: =SUM(E33:P33) -> 37800 | S33: {=SUM(INDIRECT(ADDRESS(expenses_min_row,COLUMN()) & ":" & ADDRESS(expenses_max_row, COLUMN())))} -> 0 | T33: {=SUM(INDIRECT(ADDRESS(expenses_min_row,COLUMN()) & ":" & ADDRESS(expenses_max_row, COLUMN())))} -> 0 | U33: {=SUM(INDIRECT(ADDRESS(expenses_min_row,COLUMN()) & ":" & ADDRESS(expenses_max_row, COLUMN())))} -> 0 | V33: {=SUM(INDIRECT(ADDRESS(expenses_min_row,COLUMN()) & ":" & ADDRESS(expenses_max_row, COLUMN())))} -> 0 | W33: {=SUM(INDIRECT(ADDRESS(expenses_min_row,COLUMN()) & ":" & ADDRESS(expenses_max_row, COLUMN())))} -> 0 | X33: {=SUM(INDIRECT(ADDRESS(expenses_min_row,COLUMN()) & ":" & ADDRESS(expenses_max_row, COLUMN())))} -> 0 | Y33: {=SUM(INDIRECT(ADDRESS(expenses_min_row,COLUMN()) & ":" & ADDRESS(expenses_max_row, COLUMN())))} -> 0 | Z33: {=SUM(INDIRECT(ADDRESS(expenses_min_row,COLUMN()) & ":" & ADDRESS(expenses_max_row, COLUMN())))} -> 0 | ... AD33: {=SUM(INDIRECT(ADDRESS(expenses_min_row,COLUMN()) & ":" & ADDRESS(expenses_max_row, COLUMN())))} -> 0 | AE33: =SUM(S33:AD33) -> 0 | AG33: {=SUM(INDIRECT(ADDRESS(expenses_min_row,COLUMN()) & ":" & ADDRESS(expenses_max_row, COLUMN())))} -> 0 | AH33: {=SUM(INDIRECT(ADDRESS(expenses_min_row,COLUMN()) & ":" & ADDRESS(expenses_max_row, COLUMN())))} -> 0 | AI33: {=SUM(INDIRECT(ADDRESS(expenses_min_row,COLUMN()) & ":" & ADDRESS(expenses_max_row, COLUMN())))} -> 0 | AJ33: {=SUM(INDIRECT(ADDRESS(expenses_min_row,COLUMN()) & ":" & ADDRESS(expenses_max_row, COLUMN())))} -> 0 | AK33: {=SUM(INDIRECT(ADDRESS(expenses_min_row,COLUMN()) & ":" & ADDRESS(expenses_max_row, COLUMN())))} -> 0 | AL33: {=SUM(INDIRECT(ADDRESS(expenses_min_row,COLUMN()) & ":" & ADDRESS(expenses_max_row, COLUMN())))} -> 0 | AM33: {=SUM(INDIRECT(ADDRESS(expenses_min_row,COLUMN()) & ":" & ADDRESS(expenses_max_row, COLUMN())))} -> 0 | AN33: {=SUM(INDIRECT(ADDRESS(expenses_min_row,COLUMN()) & ":" & ADDRESS(expenses_max_row, COLUMN())))} -> 0 | ... AR33: {=SUM(INDIRECT(ADDRESS(expenses_min_row,COLUMN()) & ":" & ADDRESS(expenses_max_row, COLUMN())))} -> 0 | AS33: =SUM(AG33:AR33) -> 0 | AU33: {=SUM(INDIRECT(ADDRESS(expenses_min_row,COLUMN()) & ":" & ADDRESS(expenses_max_row, COLUMN())))} -> 0 | AV33: {=SUM(INDIRECT(ADDRESS(expenses_min_row,COLUMN()) & ":" & ADDRESS(expenses_max_row, COLUMN())))} -> 0 | AW33: {=SUM(INDIRECT(ADDRESS(expenses_min_row,COLUMN()) & ":" & ADDRESS(expenses_max_row, COLUMN())))} -> 0 | AX33: {=SUM(INDIRECT(ADDRESS(expenses_min_row,COLUMN()) & ":" & ADDRESS(expenses_max_row, COLUMN())))} -> 0 | AY33: {=SUM(INDIRECT(ADDRESS(expenses_min_row,COLUMN()) & ":" & ADDRESS(expenses_max_row, COLUMN())))} -> 0 | AZ33: {=SUM(INDIRECT(ADDRESS(expenses_min_row,COLUMN()) & ":" & ADDRESS(expenses_max_row, COLUMN())))} -> 0 | BA33: {=SUM(INDIRECT(ADDRESS(expenses_min_row,COLUMN()) & ":" & ADDRESS(expenses_max_row, COLUMN())))} -> 0 | BB33: {=SUM(INDIRECT(ADDRESS(expenses_min_row,COLUMN()) & ":" & ADDRESS(expenses_max_row, COLUMN())))} -> 0 | ... BF33: {=SUM(INDIRECT(ADDRESS(expenses_min_row,COLUMN()) & ":" & ADDRESS(expenses_max_row, COLUMN())))} -> 0 | BG33: =SUM(AU33:BF33) -> 0 | BI33: {=SUM(INDIRECT(ADDRESS(expenses_min_row,COLUMN()) & ":" & ADDRESS(expenses_max_row, COLUMN())))} -> 0 | BJ33: {=SUM(INDIRECT(ADDRESS(expenses_min_row,COLUMN()) & ":" & ADDRESS(expenses_max_row, COLUMN())))} -> 0 | BK33: {=SUM(INDIRECT(ADDRESS(expenses_min_row,COLUMN()) & ":" & ADDRESS(expenses_max_row, COLUMN())))} -> 0 | BL33: {=SUM(INDIRECT(ADDRESS(expenses_min_row,COLUMN()) & ":" & ADDRESS(expenses_max_row, COLUMN())))} -> 0 | BM33: {=SUM(INDIRECT(ADDRESS(expenses_min_row,COLUMN()) & ":" & ADDRESS(expenses_max_row, COLUMN())))} -> 0 | BN33: {=SUM(INDIRECT(ADDRESS(expenses_min_row,COLUMN()) & ":" & ADDRESS(expenses_max_row, COLUMN())))} -> 0 | BO33: {=SUM(INDIRECT(ADDRESS(expenses_min_row,COLUMN()) & ":" & ADDRESS(expenses_max_row, COLUMN())))} -> 0 | BP33: {=SUM(INDIRECT(ADDRESS(expenses_min_row,COLUMN()) & ":" & ADDRESS(expenses_max_row, COLUMN())))} -> 0 | ... BT33: {=SUM(INDIRECT(ADDRESS(expenses_min_row,COLUMN()) & ":" & ADDRESS(expenses_max_row, COLUMN())))} -> 0 | BU33: =SUM(BI33:BT33) -> 0 | BW33: {=SUM(INDIRECT(ADDRESS(expenses_min_row,COLUMN()) & ":" & ADDRESS(expenses_max_row, COLUMN())))} -> 0 | BX33: {=SUM(INDIRECT(ADDRESS(expenses_min_row,COLUMN()) & ":" & ADDRESS(expenses_max_row, COLUMN())))} -> 0 | BY33: {=SUM(INDIRECT(ADDRESS(expenses_min_row,COLUMN()) & ":" & ADDRESS(expenses_max_row, COLUMN())))} -> 0 | BZ33: {=SUM(INDIRECT(ADDRESS(expenses_min_row,COLUMN()) & ":" & ADDRESS(expenses_max_row, COLUMN())))} -> 0 | CA33: {=SUM(INDIRECT(ADDRESS(expenses_min_row,COLUMN()) & ":" & ADDRESS(expenses_max_row, COLUMN())))} -> 0 | CB33: {=SUM(INDIRECT(ADDRESS(expenses_min_row,COLUMN()) & ":" & ADDRESS(expenses_max_row, COLUMN())))} -> 0 | CC33: {=SUM(INDIRECT(ADDRESS(expenses_min_row,COLUMN()) & ":" & ADDRESS(expenses_max_row, COLUMN())))} -> 0 | CD33: {=SUM(INDIRECT(ADDRESS(expenses_min_row,COLUMN()) & ":" & ADDRESS(expenses_max_row, COLUMN())))} -> 0 | ... CH33: {=SUM(INDIRECT(ADDRESS(expenses_min_row,COLUMN()) & ":" & ADDRESS(expenses_max_row, COLUMN())))} -> 0 | CI33: =SUM(BW33:CH33) -> 0 | CK33: {=SUM(INDIRECT(ADDRESS(expenses_min_row,COLUMN()) & ":" & ADDRESS(expenses_max_row, COLUMN())))} -> 0 | CL33: {=SUM(INDIRECT(ADDRESS(expenses_min_row,COLUMN()) & ":" & ADDRESS(expenses_max_row, COLUMN())))} -> 0 | CM33: {=SUM(INDIRECT(ADDRESS(expenses_min_row,COLUMN()) & ":" & ADDRESS(expenses_max_row, COLUMN())))} -> 0 | CN33: {=SUM(INDIRECT(ADDRESS(expenses_min_row,COLUMN()) & ":" & ADDRESS(expenses_max_row, COLUMN())))} -> 0 | CO33: {=SUM(INDIRECT(ADDRESS(expenses_min_row,COLUMN()) & ":" & ADDRESS(expenses_max_row, COLUMN())))} -> 0 | CP33: {=SUM(INDIRECT(ADDRESS(expenses_min_row,COLUMN()) & ":" & ADDRESS(expenses_max_row, COLUMN())))} -> 0 | CQ33: {=SUM(INDIRECT(ADDRESS(expenses_min_row,COLUMN()) & ":" & ADDRESS(expenses_max_row, COLUMN())))} -> 0 | CR33: {=SUM(INDIRECT(ADDRESS(expenses_min_row,COLUMN()) & ":" & ADDRESS(expenses_max_row, COLUMN())))} -> 0 | ... CV33: {=SUM(INDIRECT(ADDRESS(expenses_min_row,COLUMN()) & ":" & ADDRESS(expenses_max_row, COLUMN())))} -> 0 | CW33: =SUM(CK33:CV33) -> 0 | CY33: {=SUM(INDIRECT(ADDRESS(expenses_min_row,COLUMN()) & ":" & ADDRESS(expenses_max_row, COLUMN())))} -> 0 | CZ33: {=SUM(INDIRECT(ADDRESS(expenses_min_row,COLUMN()) & ":" & ADDRESS(expenses_max_row, COLUMN())))} -> 0 | DA33: {=SUM(INDIRECT(ADDRESS(expenses_min_row,COLUMN()) & ":" & ADDRESS(expenses_max_row, COLUMN())))} -> 0 | DB33: {=SUM(INDIRECT(ADDRESS(expenses_min_row,COLUMN()) & ":" & ADDRESS(expenses_max_row, COLUMN())))} -> 0 | DC33: {=SUM(INDIRECT(ADDRESS(expenses_min_row,COLUMN()) & ":" & ADDRESS(expenses_max_row, COLUMN())))} -> 0 | DD33: {=SUM(INDIRECT(ADDRESS(expenses_min_row,COLUMN()) & ":" & ADDRESS(expenses_max_row, COLUMN())))} -> 0 | DE33: {=SUM(INDIRECT(ADDRESS(expenses_min_row,COLUMN()) & ":" & ADDRESS(expenses_max_row, COLUMN())))} -> 0 | DF33: {=SUM(INDIRECT(ADDRESS(expenses_min_row,COLUMN()) & ":" & ADDRESS(expenses_max_row, COLUMN())))} -> 0 | ... DJ33: {=SUM(INDIRECT(ADDRESS(expenses_min_row,COLUMN()) & ":" & ADDRESS(expenses_max_row, COLUMN())))} -> 0 | DK33: =SUM(CY33:DJ33) -> 0 | DM33: {=SUM(INDIRECT(ADDRESS(expenses_min_row,COLUMN()) & ":" & ADDRESS(expenses_max_row, COLUMN())))} -> 0 | DN33: {=SUM(INDIRECT(ADDRESS(expenses_min_row,COLUMN()) & ":" & ADDRESS(expenses_max_row, COLUMN())))} -> 0 | DO33: {=SUM(INDIRECT(ADDRESS(expenses_min_row,COLUMN()) & ":" & ADDRESS(expenses_max_row, COLUMN())))} -> 0 | DP33: {=SUM(INDIRECT(ADDRESS(expenses_min_row,COLUMN()) & ":" & ADDRESS(expenses_max_row, COLUMN())))} -> 0 | DQ33: {=SUM(INDIRECT(ADDRESS(expenses_min_row,COLUMN()) & ":" & ADDRESS(expenses_max_row, COLUMN())))} -> 0 | DR33: {=SUM(INDIRECT(ADDRESS(expenses_min_row,COLUMN()) & ":" & ADDRESS(expenses_max_row, COLUMN())))} -> 0 | DS33: {=SUM(INDIRECT(ADDRESS(expenses_min_row,COLUMN()) & ":" & ADDRESS(expenses_max_row, COLUMN())))} -> 0 | DT33: {=SUM(INDIRECT(ADDRESS(expenses_min_row,COLUMN()) & ":" & ADDRESS(expenses_max_row, COLUMN())))} -> 0 | ... DX33: {=SUM(INDIRECT(ADDRESS(expenses_min_row,COLUMN()) & ":" & ADDRESS(expenses_max_row, COLUMN())))} -> 0 | DY33: =SUM(DM33:DX33) -> 0
C35: Savings | E35: =DATE(E$5,1,1) -> 44562 | F35: =DATE(E$5,2,1) -> 44593 | G35: =DATE(E$5,3,1) -> 44621 | H35: =DATE(E$5,4,1) -> 44652 | I35: =DATE(E$5,5,1) -> 44682 | J35: =DATE(E$5,6,1) -> 44713 | K35: =DATE(E$5,7,1) -> 44743 | L35: =DATE(E$5,8,1) -> 44774 | M35: =DATE(E$5,9,1) -> 44805 | N35: =DATE(E$5,10,1) -> 44835 | O35: =DATE(E$5,11,1) -> 44866 | P35: =DATE(E$5,12,1) -> 44896 | Q35: 2022 | S35: =DATE(S$5,1,1) -> 44927 | T35: =DATE(S$5,2,1) -> 44958 | U35: =DATE(S$5,3,1) -> 44986 | V35: =DATE(S$5,4,1) -> 45017 | W35: =DATE(S$5,5,1) -> 45047 | X35: =DATE(S$5,6,1) -> 45078 | Y35: =DATE(S$5,7,1) -> 45108 | Z35: =DATE(S$5,8,1) -> 45139 | AA35: =DATE(S$5,9,1) -> 45170 | AB35: =DATE(S$5,10,1) -> 45200 | AC35: =DATE(S$5,11,1) -> 45231 | AD35: =DATE(S$5,12,1) -> 45261 | AE35: =Q35+1 -> 2023 | AG35: =DATE(AG$5,1,1) -> 45292 | AH35: =DATE(AG$5,2,1) -> 45323 | AI35: =DATE(AG$5,3,1) -> 45352 | AJ35: =DATE(AG$5,4,1) -> 45383 | AK35: =DATE(AG$5,5,1) -> 45413 | AL35: =DATE(AG$5,6,1) -> 45444 | AM35: =DATE(AG$5,7,1) -> 45474 | AN35: =DATE(AG$5,8,1) -> 45505 | AO35: =DATE(AG$5,9,1) -> 45536 | AP35: =DATE(AG$5,10,1) -> 45566 | AQ35: =DATE(AG$5,11,1) -> 45597 | AR35: =DATE(AG$5,12,1) -> 45627 | AS35: =AE35+1 -> 2024 | AU35: =DATE(AU$5,1,1) -> 45658 | AV35: =DATE(AU$5,2,1) -> 45689 | AW35: =DATE(AU$5,3,1) -> 45717 | AX35: =DATE(AU$5,4,1) -> 45748 | AY35: =DATE(AU$5,5,1) -> 45778 | AZ35: =DATE(AU$5,6,1) -> 45809 | BA35: =DATE(AU$5,7,1) -> 45839 | BB35: =DATE(AU$5,8,1) -> 45870 | BC35: =DATE(AU$5,9,1) -> 45901 | BD35: =DATE(AU$5,10,1) -> 45931 | BE35: =DATE(AU$5,11,1) -> 45962 | BF35: =DATE(AU$5,12,1) -> 45992 | BG35: =AS35+1 -> 2025 | BI35: =DATE(BI$5,1,1) -> 46023 | BJ35: =DATE(BI$5,2,1) -> 46054 | BK35: =DATE(BI$5,3,1) -> 46082 | BL35: =DATE(BI$5,4,1) -> 46113 | BM35: =DATE(BI$5,5,1) -> 46143 | BN35: =DATE(BI$5,6,1) -> 46174 | BO35: =DATE(BI$5,7,1) -> 46204 | BP35: =DATE(BI$5,8,1) -> 46235 | BQ35: =DATE(BI$5,9,1) -> 46266 | BR35: =DATE(BI$5,10,1) -> 46296 | BS35: =DATE(BI$5,11,1) -> 46327 | BT35: =DATE(BI$5,12,1) -> 46357 | BU35: =BG35+1 -> 2026 | BW35: =DATE(BW$5,1,1) -> 46388 | BX35: =DATE(BW$5,2,1) -> 46419 | BY35: =DATE(BW$5,3,1) -> 46447 | BZ35: =DATE(BW$5,4,1) -> 46478 | CA35: =DATE(BW$5,5,1) -> 46508 | CB35: =DATE(BW$5,6,1) -> 46539 | CC35: =DATE(BW$5,7,1) -> 46569 | CD35: =DATE(BW$5,8,1) -> 46600 | CE35: =DATE(BW$5,9,1) -> 46631 | CF35: =DATE(BW$5,10,1) -> 46661 | CG35: =DATE(BW$5,11,1) -> 46692 | CH35: =DATE(BW$5,12,1) -> 46722 | CI35: =BU35+1 -> 2027 | CK35: =DATE(CK$5,1,1) -> 46753 | CL35: =DATE(CK$5,2,1) -> 46784 | CM35: =DATE(CK$5,3,1) -> 46813 | CN35: =DATE(CK$5,4,1) -> 46844 | CO35: =DATE(CK$5,5,1) -> 46874 | CP35: =DATE(CK$5,6,1) -> 46905 | CQ35: =DATE(CK$5,7,1) -> 46935 | CR35: =DATE(CK$5,8,1) -> 46966 | CS35: =DATE(CK$5,9,1) -> 46997 | CT35: =DATE(CK$5,10,1) -> 47027 | CU35: =DATE(CK$5,11,1) -> 47058 | CV35: =DATE(CK$5,12,1) -> 47088 | CW35: =CI35+1 -> 2028 | CY35: =DATE(CY$5,1,1) -> 47119 | CZ35: =DATE(CY$5,2,1) -> 47150 | DA35: =DATE(CY$5,3,1) -> 47178 | DB35: =DATE(CY$5,4,1) -> 47209 | DC35: =DATE(CY$5,5,1) -> 47239 | DD35: =DATE(CY$5,6,1) -> 47270 | DE35: =DATE(CY$5,7,1) -> 47300 | DF35: =DATE(CY$5,8,1) -> 47331 | DG35: =DATE(CY$5,9,1) -> 47362 | DH35: =DATE(CY$5,10,1) -> 47392 | DI35: =DATE(CY$5,11,1) -> 47423 | DJ35: =DATE(CY$5,12,1) -> 47453 | DK35: =CW35+1 -> 2029 | DM35: =DATE(DM$5,1,1) -> 47484 | DN35: =DATE(DM$5,2,1) -> 47515 | DO35: =DATE(DM$5,3,1) -> 47543 | DP35: =DATE(DM$5,4,1) -> 47574 | DQ35: =DATE(DM$5,5,1) -> 47604 | DR35: =DATE(DM$5,6,1) -> 47635 | DS35: =DATE(DM$5,7,1) -> 47665 | DT35: =DATE(DM$5,8,1) -> 47696 | DU35: =DATE(DM$5,9,1) -> 47727 | DV35: =DATE(DM$5,10,1) -> 47757 | DW35: =DATE(DM$5,11,1) -> 47788 | DX35: =DATE(DM$5,12,1) -> 47818 | DY35: =DK35+1 -> 2030
C36: Emergency Fund | E36: 1000 | F36: 1000 | G36: 1000 | H36: 0 | I36: 0 | J36: 0 | K36: 0 | L36: 0 | M36: 0 | N36: 0 | O36: 0 | P36: 0 | Q36: =SUM(E36:P36) -> 3000 | AE36: =SUM(S36:AD36) -> 0 | AS36: =SUM(AG36:AR36) -> 0 | BG36: =SUM(AU36:BF36) -> 0 | BU36: =SUM(BI36:BT36) -> 0 | CI36: =SUM(BW36:CH36) -> 0 | CW36: =SUM(CK36:CV36) -> 0 | DK36: =SUM(CY36:DJ36) -> 0 | DY36: =SUM(DM36:DX36) -> 0
C37: Retirement Account | E37: 400 | F37: 400 | G37: 400 | H37: 400 | I37: 400 | J37: 400 | K37: 400 | L37: 400 | M37: 400 | N37: 400 | O37: 400 | P37: 400 | Q37: =SUM(E37:P37) -> 4800 | AE37: =SUM(S37:AD37) -> 0 | AS37: =SUM(AG37:AR37) -> 0 | BG37: =SUM(AU37:BF37) -> 0 | BU37: =SUM(BI37:BT37) -> 0 | CI37: =SUM(BW37:CH37) -> 0 | CW37: =SUM(CK37:CV37) -> 0 | DK37: =SUM(CY37:DJ37) -> 0 | DY37: =SUM(DM37:DX37) -> 0
C38: Stock Portfolio | E38: 150 | F38: 150 | G38: 150 | H38: 750 | I38: 750 | J38: 750 | K38: 750 | L38: 750 | M38: 750 | N38: 750 | O38: 750 | P38: 750 | Q38: =SUM(E38:P38) -> 7200 | AE38: =SUM(S38:AD38) -> 0 | AS38: =SUM(AG38:AR38) -> 0 | BG38: =SUM(AU38:BF38) -> 0 | BU38: =SUM(BI38:BT38) -> 0 | CI38: =SUM(BW38:CH38) -> 0 | CW38: =SUM(CK38:CV38) -> 0 | DK38: =SUM(CY38:DJ38) -> 0 | DY38: =SUM(DM38:DX38) -> 0
C39: Sinking Fund | E39: 0 | F39: 0 | G39: 0 | H39: 600 | I39: 1400 | J39: 1300 | K39: 1500 | L39: 200 | M39: 1300 | N39: 1500 | O39: 1400 | P39: 1000 | Q39: =SUM(E39:P39) -> 10200 | AE39: =SUM(S39:AD39) -> 0 | AS39: =SUM(AG39:AR39) -> 0 | BG39: =SUM(AU39:BF39) -> 0 | BU39: =SUM(BI39:BT39) -> 0 | CI39: =SUM(BW39:CH39) -> 0 | CW39: =SUM(CK39:CV39) -> 0 | DK39: =SUM(CY39:DJ39) -> 0 | DY39: =SUM(DM39:DX39) -> 0
C40: Sinking fund rest | E40: 200 | F40: 100 | G40: 0 | H40: 100 | I40: 100 | J40: 100 | K40: 100 | L40: 100 | M40: 100 | N40: 100 | O40: 100 | P40: 100 | Q40: =SUM(E40:P40) -> 1200 | AE40: =SUM(S40:AD40) -> 0 | AS40: =SUM(AG40:AR40) -> 0 | BG40: =SUM(AU40:BF40) -> 0 | BU40: =SUM(BI40:BT40) -> 0 | CI40: =SUM(BW40:CH40) -> 0 | CW40: =SUM(CK40:CV40) -> 0 | DK40: =SUM(CY40:DJ40) -> 0 | DY40: =SUM(DM40:DX40) -> 0
C41: Enter savings Category | Q41: =SUM(E41:P41) -> 0 | AE41: =SUM(S41:AD41) -> 0 | AS41: =SUM(AG41:AR41) -> 0 | BG41: =SUM(AU41:BF41) -> 0 | BU41: =SUM(BI41:BT41) -> 0 | CI41: =SUM(BW41:CH41) -> 0 | CW41: =SUM(CK41:CV41) -> 0 | DK41: =SUM(CY41:DJ41) -> 0 | DY41: =SUM(DM41:DX41) -> 0
C42: Entersavings Category | Q42: =SUM(E42:P42) -> 0 | AE42: =SUM(S42:AD42) -> 0 | AS42: =SUM(AG42:AR42) -> 0 | BG42: =SUM(AU42:BF42) -> 0 | BU42: =SUM(BI42:BT42) -> 0 | CI42: =SUM(BW42:CH42) -> 0 | CW42: =SUM(CK42:CV42) -> 0 | DK42: =SUM(CY42:DJ42) -> 0 | DY42: =SUM(DM42:DX42) -> 0
C43: Enter savings Category | Q43: =SUM(E43:P43) -> 0 | AE43: =SUM(S43:AD43) -> 0 | AS43: =SUM(AG43:AR43) -> 0 | BG43: =SUM(AU43:BF43) -> 0 | BU43: =SUM(BI43:BT43) -> 0 | CI43: =SUM(BW43:CH43) -> 0 | CW43: =SUM(CK43:CV43) -> 0 | DK43: =SUM(CY43:DJ43) -> 0 | DY43: =SUM(DM43:DX43) -> 0
C44: Enter savings Category | Q44: =SUM(E44:P44) -> 0 | AE44: =SUM(S44:AD44) -> 0 | AS44: =SUM(AG44:AR44) -> 0 | BG44: =SUM(AU44:BF44) -> 0 | BU44: =SUM(BI44:BT44) -> 0 | CI44: =SUM(BW44:CH44) -> 0 | CW44: =SUM(CK44:CV44) -> 0 | DK44: =SUM(CY44:DJ44) -> 0 | DY44: =SUM(DM44:DX44) -> 0
C45: Enter savings Category | Q45: =SUM(E45:P45) -> 0 | AE45: =SUM(S45:AD45) -> 0 | AS45: =SUM(AG45:AR45) -> 0 | BG45: =SUM(AU45:BF45) -> 0 | BU45: =SUM(BI45:BT45) -> 0 | CI45: =SUM(BW45:CH45) -> 0 | CW45: =SUM(CK45:CV45) -> 0 | DK45: =SUM(CY45:DJ45) -> 0 | DY45: =SUM(DM45:DX45) -> 0
